Workbook

Sheet Source
A1: Number | B1: Letter | D1: السنة الحالية | E1: السنة الجديدة
A2: 1 | B2: A_ | D2: الاول الابتدائي | E2: الثاني الابتدائي
A3: =A2+1 -> 2 | B3: B_ | D3: الثاني الابتدائي | E3: الثالث الابتدائي
A4: =A3+1 -> 3 | B4: C_ | D4: الثالث الابتدائي | E4: الرابع الابتدائي
A5: =A4+1 -> 4 | B5: D_ | D5: الرابع الابتدائي | E5: الخامس الابتدائي
A6: =A5+1 -> 5 | B6: E_ | D6: الخامس الابتدائي | E6: السادس الابتدائي
A7: =A6+1 -> 6 | B7: F_ | D7: السادس الابتدائي | E7: الاول الاعدادي
A8: =A7+1 -> 7 | B8: G_ | D8: الاول الاعدادي | E8: الثاني الاعدادي
A9: =A8+1 -> 8 | B9: H_ | D9: الثاني الاعدادي | E9: الثالث الاعدادي
A10: =A9+1 -> 9 | B10: I_ | D10: الثالث الاعدادي | E10: الأول الثانوي
A11: =A10+1 -> 10 | B11: J_ | D11: الأول الثانوي | E11: الثاني الثانوي
A12: =A11+1 -> 11 | B12: K_ | D12: الثاني الثانوي | E12: الثالث الثانوي
A13: =A12+1 -> 12 | B13: L_ | D13: الثالث الثانوي | E13: خاريجات
A14: =A13+1 -> 13 | B14: M_ | D14: خاريجات | E14: خاريجات
A15: =A14+1 -> 14 | B15: N_
A16: =A15+1 -> 15 | B16: O_
A17: =A16+1 -> 16 | B17: P_
A18: =A17+1 -> 17 | B18: Q_
A19: =A18+1 -> 18 | B19: R_
A20: =A19+1 -> 19 | B20: S_
A21: =A20+1 -> 20 | B21: T_
A22: =A21+1 -> 21 | B22: U_
A23: =A22+1 -> 22 | B23: V_
A24: =A23+1 -> 23 | B24: W_
A25: =A24+1 -> 24 | B25: X_
A26: =A25+1 -> 25 | B26: Y_
A27: =A26+1 -> 26 | B27: Z_

Sheet Database
A1: Timestamp | B1: Email Address | C1: Code | D1: اسم الطالبة رباعيًا | E1: اسم الطالبة باللغة الانجليزية | F1: الفصل | G1: تـاريخ الميلاد | H1: وظيفـة الأب | I1: وظيفــة الأم | J1: موبـايل الأب | K1: موبـايل الأم | L1: العنوان بالتفصيل | M1: التنويه لوجود أى حالة مرضية | N1: المواهب و المهارات | O1: الرقم القومي | P1: Column1 | R1: s | XFC1: Letter | XFD1: Number
A2: 45703.506 | B2: nerminsayed450@gmail.com | C2: =_xlfn.CONCAT(XFC2:XFD2) -> A_250001 | D2: هيڤين ياسر السيد قطب | E2: Heaven Yasser El Sayed Kotb | F2: السادس الابتدائي | G2: 41667 | H2: محاسب | I2: مدرسة | J2: 01032677148 | K2: 01014306267 | L2: العبور الحي التاسع شارع عبد العزيز الشوان متفرع من شارع الجامعة بلوك 82 عمارة 5 الدور التالت شقة 8 | M2: لا يوجد | N2: الرسم ولعب الباسكت | R2: =VLOOKUP(DataBase[[#This Row],[الفصل]],المرحلة_الدراسية[],2,0) -> الاول الاعدادي | XFC2: =VLOOKUP(COUNTIF($XFD$2:XFD2,250001),Table3[],2,0) -> A_ | XFD2: 250001
A3: 45703.51 | B3: rehammagdy214@gmail.com | C3: =_xlfn.CONCAT(XFC3:XFD3) -> A_250002 | D3: ترينتى رجائى نسيم ملك | E3: Trinity Ragaay Nessim malak | F3: السادس الابتدائي | G3: 41641 | H3: محامي | I3: محامية | J3: 01225970823 | K3: 01272995022 | L3: دار مصر المرحله التانيه الحى التاسع العبور | M3: حساسية صدر | N3: التمثيل.. كورال... رسم..تفصيل... اعمال فنيه | O3: 31401020100705 | R3: =VLOOKUP(DataBase[[#This Row],[الفصل]],المرحلة_الدراسية[],2,0) -> الاول الاعدادي | XFC3: =VLOOKUP(COUNTIF($XFD$2:XFD3,250001),Table3[],2,0) -> A_ | XFD3: =IF(XFD2+1=260000,250001,XFD2+1) -> 250002
A4: 45703.511 | B4: marymelek777@gmail.com | C4: =_xlfn.CONCAT(XFC4:XFD4) -> A_250003 | D4: مارينا ملك بخيت ملك | E4: Marina Melek Bekhit Melek | F4: الثاني الاعدادي | G4: 40977 | H4: محاسب شركة انسيا | I4: طبيبة بيطرية | J4: 01223366700 | K4: 01205080177 | L4: 24جولدن هاوس المستثمر الصغير خلف القديس يوسف | M4: لا يوجد | N4: القيادة والصوت الجميل | O4: 31203092501686 | R4: =VLOOKUP(DataBase[[#This Row],[الفصل]],المرحلة_الدراسية[],2,0) -> الثالث الاعدادي | XFC4: =VLOOKUP(COUNTIF($XFD$2:XFD4,250001),Table3[],2,0) -> A_ | XFD4: =IF(XFD3+1=260000,250001,XFD3+1) -> 250003
A5: 45703.512 | B5: marinajunier89@gmail.com | C5: =_xlfn.CONCAT(XFC5:XFD5) -> A_250004 | D5: جونير بيشوى ظريف | E5: Junier Beshoy Zarif | F5: السادس الابتدائي | G5: 41849 | H5: صاحب شركه موازين | I5: Sales international at spicekingdom | J5: 01254333987 | K5: 01277035552 | L5: العبور الحى التانى فيلا ٨٤ أمام المرور | M5: لا يوجد | N5: تمثيل و التلوين | R5: =VLOOKUP(DataBase[[#This Row],[الفصل]],المرحلة_الدراسية[],2,0) -> الاول الاعدادي | XFC5: =VLOOKUP(COUNTIF($XFD$2:XFD5,250001),Table3[],2,0) -> A_ | XFD5: =IF(XFD4+1=260000,250001,XFD4+1) -> 250004
A6: 45703.515 | B6: aivywael630@gmail.com | C6: =_xlfn.CONCAT(XFC6:XFD6) -> A_250005 | D6: ايڤى وائل موريس ابادير | E6: Aivy wael Morris abadeer | F6: السادس الابتدائي | G6: 41886 | H6: مدير فى شركة الميرى للأدوية | I6: محاسبة بالشركة المصرية للإتصالات | J6: 01221212417 | K6: 01552204480 | L6: ٢٠ ش عمار بن ياسر خلف المرور مدينة السلام | M6: لا يوجد | N6: الرسم | O6: 31409040104848 | R6: =VLOOKUP(DataBase[[#This Row],[الفصل]],المرحلة_الدراسية[],2,0) -> الاول الاعدادي | XFC6: =VLOOKUP(COUNTIF($XFD$2:XFD6,250001),Table3[],2,0) -> A_ | XFD6: =IF(XFD5+1=260000,250001,XFD5+1) -> 250005
A7: 45703.518 | B7: marwaalshall2@gmail.com | C7: =_xlfn.CONCAT(XFC7:XFD7) -> A_250006 | D7: ملك أشرف حامد الكيلاني | E7: Malak Ashraf Hamed Elkelany | F7: الاول الاعدادي | G7: 41228 | H7: محاسب بشركه شمال القاهره للكهرباء | I7: أخصائي تحاليل طبيه بمعامل البرج | J7: 01006044211 | K7: 01225643326 | L7: العبور الحي الثاني محليه 34 شارع 16 قطعه 79 | M7: نزيف من الانف | N7: قراءه برمجه | O7: 31211150101122 | R7: =VLOOKUP(DataBase[[#This Row],[الفصل]],المرحلة_الدراسية[],2,0) -> الثاني الاعدادي | XFC7: =VLOOKUP(COUNTIF($XFD$2:XFD7,250001),Table3[],2,0) -> A_ | XFD7: =IF(XFD6+1=260000,250001,XFD6+1) -> 250006
A8: 45703.522 | B8: marmartony2014@gmail.com | C8: =_xlfn.CONCAT(XFC8:XFD8) -> A_250007 | D8: ايرينى مجدى شوقى انطون | E8: Eriny Magdy shawky anton | F8: السادس الابتدائي | G8: 41852 | H8: صاحب محل موبايلات | I8: ربه منزل | J8: 01050006424 | K8: 01275561556 | L8: 78 شارع الجامع قباء جسر السويس | M8: لا يوجد | N8: التمثيل | R8: =VLOOKUP(DataBase[[#This Row],[الفصل]],المرحلة_الدراسية[],2,0) -> الاول الاعدادي | XFC8: =VLOOKUP(COUNTIF($XFD$2:XFD8,250001),Table3[],2,0) -> A_ | XFD8: =IF(XFD7+1=260000,250001,XFD7+1) -> 250007
A9: 45703.53 | B9: hova.george2014@gmail.com | C9: =_xlfn.CONCAT(XFC9:XFD9) -> A_250008 | D9: هيفين جورج حنا سليمان | E9: Heaven George | F9: السادس الابتدائي | G9: 41905 | H9: محاسب | I9: ادارية في شركة طيران | J9: 01225228920 | K9: 01227774987 | L9: 59 تعاونيات شيراتون الدور ال3شقة 11 | M9: لا | N9: الجمباز و الرسم | O9: 31409230100644 | R9: =VLOOKUP(DataBase[[#This Row],[الفصل]],المرحلة_الدراسية[],2,0) -> الاول الاعدادي | XFC9: =VLOOKUP(COUNTIF($XFD$2:XFD9,250001),Table3[],2,0) -> A_ | XFD9: =IF(XFD8+1=260000,250001,XFD8+1) -> 250008
A10: 45703.532 | B10: nadia7.2014@gmail.com | C10: =_xlfn.CONCAT(XFC10:XFD10) -> A_250009 | D10: ناديا احمد وجدي السنوسي | E10: Nadeia Ahmed Wagdy Elsnosy | F10: الاول الاعدادي | G10: 41470 | H10: مدير فرع الشركة الاماراتيه للتامين | I10: مهندسة معماريه | J10: 01090999350 | K10: 01022833025 | L10: شارع 50 الحي الاول عمارة 2 مدينة العبور | M10: لا يوجد | N10: سباحه وتلوين | O10: 31307150104102 | R10: =VLOOKUP(DataBase[[#This Row],[الفصل]],المرحلة_الدراسية[],2,0) -> الثاني الاعدادي | XFC10: =VLOOKUP(COUNTIF($XFD$2:XFD10,250001),Table3[],2,0) -> A_ | XFD10: =IF(XFD9+1=260000,250001,XFD9+1) -> 250009
A11: 45703.533 | B11: marinamelek4@gmail.com | C11: =_xlfn.CONCAT(XFC11:XFD11) -> A_250010 | D11: مهرائيل ملك بخيت ملك | E11: Mehrail Melek Bekhit Melek | F11: السادس الابتدائي | G11: 41679 | H11: محاسب في شركة انسيا | I11: طبيبة بيطرية | J11: 01223366700 | K11: 01205080177 | L11: 24جولدن هاوس المستثمر الصغير خلف القديس يوسف العبور | M11: لا يوجد | N11: الصوت الجميل والقيادة | O11: 31402092501964 | R11: =VLOOKUP(DataBase[[#This Row],[الفصل]],المرحلة_الدراسية[],2,0) -> الاول الاعدادي | XFC11: =VLOOKUP(COUNTIF($XFD$2:XFD11,250001),Table3[],2,0) -> A_ | XFD11: =IF(XFD10+1=260000,250001,XFD10+1) -> 250010
A12: 45703.536 | B12: marselle.zarif@saint-joseph-school.com | C12: =_xlfn.CONCAT(XFC12:XFD12) -> A_250011 | D12: بيرلا الهامي بخيت فكري | E12: Perla Elhamy Bekhet Fekry | F12: السادس الابتدائي | G12: 41781 | H12: صاحب مطعم | I12: مدرسة | J12: 01202069472 | K12: 01203187262 | L12: 198شارع 31 الشباب مدينه العبور | M12: لا بوجد | N12: الرسم | O12: 31405220100608 | R12: =VLOOKUP(DataBase[[#This Row],[الفصل]],المرحلة_الدراسية[],2,0) -> الاول الاعدادي | XFC12: =VLOOKUP(COUNTIF($XFD$2:XFD12,250001),Table3[],2,0) -> A_ | XFD12: =IF(XFD11+1=260000,250001,XFD11+1) -> 250011
A13: 45705.835 | B13: chantal.shenouda.zarif.riad@saint-joseph-school.com | C13: =_xlfn.CONCAT(XFC13:XFD13) -> A_250012 | D13: شانتال شنودة ظريف رياض | E13: Chantal shenouda zarif riad | F13: السادس الابتدائي | G13: 41591 | H13: مدير مبيعات مصنع كيروماربل للرخام والجرانيت | I13: طبيبة بيطرية واخصائى تحاليل طبية | J13: 01275155297 | K13: 01279000095 | L13: العبور الحى التالت بلوك ٢٨٠٣٣ عمارة ١٥ شارع محمد وحيد عبد الخالق الدور الاخير | M13: لا يوجد | N13: باسكت وسباحة وبيانو | O13: 31311130102186 | R13: =VLOOKUP(DataBase[[#This Row],[الفصل]],المرحلة_الدراسية[],2,0) -> الاول الاعدادي | XFC13: =VLOOKUP(COUNTIF($XFD$2:XFD13,250001),Table3[],2,0) -> A_ | XFD13: =IF(XFD12+1=260000,250001,XFD12+1) -> 250012
A14: 45703.538 | B14: rashajojo101@gmail.com | C14: =_xlfn.CONCAT(XFC14:XFD14) -> A_250013 | D14: جولى جورج عوض جرجس | E14: Julie George Awad Gergis | F14: الخامس الابتدائي | G14: 42031 | H14: مرشد سياحى | I14: دكتورة بكلية الآثار جامعة عين شمس | J14: 01278297133 | K14: 01289874445 | L14: العبور الحى الاول محلية ٦ | M14: لا يوجد | N14: الجمباز والتمثيل والاشغال اليدوية والغناء | O14: 31501270106763 | R14: =VLOOKUP(DataBase[[#This Row],[الفصل]],المرحلة_الدراسية[],2,0) -> السادس الابتدائي | XFC14: =VLOOKUP(COUNTIF($XFD$2:XFD14,250001),Table3[],2,0) -> A_ | XFD14: =IF(XFD13+1=260000,250001,XFD13+1) -> 250013
A15: 45703.539 | B15: kokeadel387@gmail.com | C15: =_xlfn.CONCAT(XFC15:XFD15) -> A_250014 | D15: نيللي شادي محمد | E15: Nelly shady mohamed | F15: الرابع الابتدائي | G15: 42382 | H15: اعمال حرة | I15: لا يوجد | J15: 01003666087 | K15: 01005202654 | L15: مدينة المستقبل امام اكوا بارك عمارة ٧٣٨ شقة ٢٤ | M15: لا يوجد | N15: رياضة الجمباز | O15: 31601130105728 | R15: =VLOOKUP(DataBase[[#This Row],[الفصل]],المرحلة_الدراسية[],2,0) -> الخامس الابتدائي | XFC15: =VLOOKUP(COUNTIF($XFD$2:XFD15,250001),Table3[],2,0) -> A_ | XFD15: =IF(XFD14+1=260000,250001,XFD14+1) -> 250014
A16: 45703.539 | B16: mosherasobhy@hotmail.com | C16: =_xlfn.CONCAT(XFC16:XFD16) -> A_250015 | D16: مريم وسام لويس شفيق | E16: Mariam wesam louis shafik | F16: الخامس الابتدائي | G16: 42129 | H16: The owner of Trianto holidays company | I16: Tourism manager at flamingo travel | J16: 01223620949 | K16: 01276758324 | L16: فيلا ٦٦ البنفسج ٤ التجمع الاول القاهرة الجديدة | M16: لا يوجد | N16: رسم - تلوين - أعمال فنية يدوية - كتابة القصص | O16: 31505052101282 | R16: =VLOOKUP(DataBase[[#This Row],[الفصل]],المرحلة_الدراسية[],2,0) -> السادس الابتدائي | XFC16: =VLOOKUP(COUNTIF($XFD$2:XFD16,250001),Table3[],2,0) -> A_ | XFD16: =IF(XFD15+1=260000,250001,XFD15+1) -> 250015
A17: 45703.539 | B17: bassantromany@gmail.com | C17: =_xlfn.CONCAT(XFC17:XFD17) -> A_250016 | D17: بريتي سامي أنور عدلي | E17: Pretty sami Anwar adly | F17: الثالث الابتدائي | G17: 42840 | H17: مهندس | I17: مدرسه | J17: 01288236660 | K17: 01227524446 | L17: الحي التاني العبور | M17: لا | N17: الرسم والتلوين | O17: 31704150103644 | R17: =VLOOKUP(DataBase[[#This Row],[الفصل]],المرحلة_الدراسية[],2,0) -> الرابع الابتدائي | XFC17: =VLOOKUP(COUNTIF($XFD$2:XFD17,250001),Table3[],2,0) -> A_ | XFD17: =IF(XFD16+1=260000,250001,XFD16+1) -> 250016
A18: 45703.539 | B18: ahmedsherif708@gmail.com | C18: =_xlfn.CONCAT(XFC18:XFD18) -> A_250017 | D18: جوزيدا أحمد محمد ابراهيم | E18: Gozida ahmed mohamed ibrahim | F18: الثالث الابتدائي | G18: 42685 | H18: Accountant | I18: Not working | J18: 01094676545 | K18: 01003606129 | L18: مدينه حتب اكتوبر طريق مصر الإسماعيلية شارع ١٦ لوك ٢٢ عماره ١١ | M18: لا يوجد | N18: الجمباز / الرسم | O18: 31611110107924 | R18: =VLOOKUP(DataBase[[#This Row],[الفصل]],المرحلة_الدراسية[],2,0) -> الرابع الابتدائي | XFC18: =VLOOKUP(COUNTIF($XFD$2:XFD18,250001),Table3[],2,0) -> A_ | XFD18: =IF(XFD17+1=260000,250001,XFD17+1) -> 250017
A19: 45703.539 | B19: lomena.hossam.rashad.gergs@saint-joseph-school.com | C19: =_xlfn.CONCAT(XFC19:XFD19) -> A_250018 | D19: لومينا حسام رشاد جرجس | E19: Lomena Hossam Rashad Gergs | F19: الثالث الابتدائي | G19: 42670 | H19: مهندس ميكانيكا سيارات حر | I19: ربه منزل | J19: 01026433446 | K19: 01023477168 | L19: الحي الثاني بجوار مدرسه ستان فورد الدوليه فيلا رقم 115 | M19: وجود حساسيه علي الصدر | N19: الرقص الغناء التمثيل المحاوره | O19: 28909013101101 | R19: =VLOOKUP(DataBase[[#This Row],[الفصل]],المرحلة_الدراسية[],2,0) -> الرابع الابتدائي | XFC19: =VLOOKUP(COUNTIF($XFD$2:XFD19,250001),Table3[],2,0) -> A_ | XFD19: =IF(XFD18+1=260000,250001,XFD18+1) -> 250018
A20: 45703.539 | B20: babyborn1982@gmail.com | C20: =_xlfn.CONCAT(XFC20:XFD20) -> A_250019 | D20: هولي رضا ناروز جرجس | E20: Holly reda narouz girges | F20: الرابع الابتدائي | G20: 46019 | H20: محاسب و رئيس قسم التخصيمات والشحن بشركه صناعه وسائل النقل | I20: باحثة شرطه بالاداره العامه لشرطه ميناء القاهره الجوي | J20: 01223912711 | K20: 01271066601 | L20: 34 شارع نورالدين الزيتون امام سنترال مصر الجديده | M20: لا يوجد | N20: جمباز و متوقف حاليا | O20: 31512280102929 | R20: =VLOOKUP(DataBase[[#This Row],[الفصل]],المرحلة_الدراسية[],2,0) -> الخامس الابتدائي | XFC20: =VLOOKUP(COUNTIF($XFD$2:XFD20,250001),Table3[],2,0) -> A_ | XFD20: =IF(XFD19+1=260000,250001,XFD19+1) -> 250019
... A29: 45703.544 | B29: mariam.mokhles89@gmail.com | C29: =_xlfn.CONCAT(XFC29:XFD29) -> A_250028 | D29: سيلينا جوزيف جمال أمين | E29: Celina Joseph gamal amen | F29: الثالث الابتدائي | G29: 42690 | H29: دكتور علاج طبيعى | I29: دكتورة علاج طبيعى | J29: 01228346734 | K29: 01287328606 | L29: مدينة المستقبل طريق مصر الإسماعيلية الصحراوى. قطاع اليو عمارة ٢٤ الدور الأول شقة ١٣ | M29: لا يوجد الحمد الله | N29: التلوين والرسم | O29: 31611160101048 | R29: =VLOOKUP(DataBase[[#This Row],[الفصل]],المرحلة_الدراسية[],2,0) -> الرابع الابتدائي | XFC29: =VLOOKUP(COUNTIF($XFD$2:XFD29,250001),Table3[],2,0) -> A_ | XFD29: =IF(XFD28+1=260000,250001,XFD28+1) -> 250028
A30: 45703.544 | B30: basmarefaat305@gmail.com | C30: =_xlfn.CONCAT(XFC30:XFD30) -> A_250029 | D30: فريدة محمد القصبي | E30: Farida Mohamed Qasby | F30: الثالث الابتدائي | G30: 42923 | H30: ظابط | I30: دكتورة | J30: 01010105752 | K30: 01029755557 | L30: مدينة مستقبل الهابكستب عمارة ٤٢٨ شقة ٦٢ | M30: لا يوجد | N30: اسكواش وسباحة ورسم | R30: =VLOOKUP(DataBase[[#This Row],[الفصل]],المرحلة_الدراسية[],2,0) -> الرابع الابتدائي | XFC30: =VLOOKUP(COUNTIF($XFD$2:XFD30,250001),Table3[],2,0) -> A_ | XFD30: =IF(XFD29+1=260000,250001,XFD29+1) -> 250029
A31: 45703.545 | B31: christinagamal367@gmail.com | C31: =_xlfn.CONCAT(XFC31:XFD31) -> A_250030 | D31: ماريتسيا سامح بطرس عبدالله | E31: Maritsia sameh botros Abdulla | F31: السادس الابتدائي | G31: 41579 | H31: مهندس | I31: مدرسه | J31: 01227656913 | K31: 01098550901 | L31: العبور الجديدة حى الكرامه ع 203 ش 11 | M31: لا يوجد | N31: رسم وعمل مجسمات اعمال فنيه ولعب كره السله | O31: 27808140101671 | R31: =VLOOKUP(DataBase[[#This Row],[الفصل]],المرحلة_الدراسية[],2,0) -> الاول الاعدادي | XFC31: =VLOOKUP(COUNTIF($XFD$2:XFD31,250001),Table3[],2,0) -> A_ | XFD31: =IF(XFD30+1=260000,250001,XFD30+1) -> 250030
A32: 45703.548 | B32: nabila.zaki77@gmail.com | C32: =_xlfn.CONCAT(XFC32:XFD32) -> A_250031 | D32: اسيل محمد مصطفى عبدالله | E32: Aseel Mohamed Mostafa Abdallh | F32: الخامس الابتدائي | G32: 41986 | H32: مدير قطاع فى شركه بترول بلاعيم | I32: مهندسه كهربا حاسبات | J32: 01226340090 | K32: 01065532002 | L32: العبور الحى الخامس بلوك 16039 شارع الفارابى فيلا 10 | M32: لا | N32: مسجله فى الاتحاد المصرى للسباحه و الاتحاد المصرى لكرة السله | R32: =VLOOKUP(DataBase[[#This Row],[الفصل]],المرحلة_الدراسية[],2,0) -> السادس الابتدائي | XFC32: =VLOOKUP(COUNTIF($XFD$2:XFD32,250001),Table3[],2,0) -> A_ | XFD32: =IF(XFD31+1=260000,250001,XFD31+1) -> 250031
A33: 45703.548 | B33: nedododo8@gmail.com | C33: =_xlfn.CONCAT(XFC33:XFD33) -> A_250032 | D33: جانسي نادر شكري جورجي | E33: Jancy Nader Shoukry Georgi | F33: الخامس الابتدائي | G33: 42175 | H33: صيدلي | I33: صيدلانية | J33: 01220831995 | K33: 01289808790 | L33: العبور الحي الثالث أمام نادي سيتي كلب | M33: لا | N33: الرسم و النشاطات الجماعية | O33: 31506200108387 | R33: =VLOOKUP(DataBase[[#This Row],[الفصل]],المرحلة_الدراسية[],2,0) -> السادس الابتدائي | XFC33: =VLOOKUP(COUNTIF($XFD$2:XFD33,250001),Table3[],2,0) -> A_ | XFD33: =IF(XFD32+1=260000,250001,XFD32+1) -> 250032
A34: 45703.551 | B34: nonnakartota@gmail.com | C34: =_xlfn.CONCAT(XFC34:XFD34) -> A_250033 | D34: تريفينا فرج ابراهيم حنا | E34: Trevena farag Ibrahim hanaa | F34: الثالث الابتدائي | G34: 42831 | H34: مدير مبيعات | I34: ربه منزل | J34: 01271421330 | K34: 01206934470 | L34: ٧الفردوس الحرفيين جسر السويس | M34: لا | N34: الرسم | O34: 28611232403475 | R34: =VLOOKUP(DataBase[[#This Row],[الفصل]],المرحلة_الدراسية[],2,0) -> الرابع الابتدائي | XFC34: =VLOOKUP(COUNTIF($XFD$2:XFD34,250001),Table3[],2,0) -> A_ | XFD34: =IF(XFD33+1=260000,250001,XFD33+1) -> 250033
A35: 45703.554 | B35: sohakamel5566@gmail.com | C35: =_xlfn.CONCAT(XFC35:XFD35) -> A_250034 | D35: فريدة نورالدين صلاح الغريب | E35: Farida Nour-Eldein Salah Algharib | F35: الرابع الابتدائي | G35: 42370 | H35: مدير عام ادارة حسابات شركة الأمل للبترول | I35: ربة منزل | J35: 01227512000 | K35: 01200095393 | L35: خلف مدرسة القديس يوسف عمارة 24 شقة 1 | M35: لا يوجد | N35: الفروسية والتلوين | O35: 21601011515284 | R35: =VLOOKUP(DataBase[[#This Row],[الفصل]],المرحلة_الدراسية[],2,0) -> الخامس الابتدائي | XFC35: =VLOOKUP(COUNTIF($XFD$2:XFD35,250001),Table3[],2,0) -> A_ | XFD35: =IF(XFD34+1=260000,250001,XFD34+1) -> 250034
A36: 45703.554 | B36: mira.m.mansour@gmail.com | C36: =_xlfn.CONCAT(XFC36:XFD36) -> A_250035 | D36: لورين خالد علي علي | E36: Lauren khaled ali ali | F36: الرابع الابتدائي | G36: 42350 | H36: لواء شرطه | I36: استشاري في الاتفاقيات التجاري الدوليه بالهيئة العامة للرقابه علي الصادرات | J36: '01090902818 | K36: 01282633328 | L36: مدينه العبور الحى السابع شارع الشهيد بدر رخا مربع 15035 فيلا 14 | M36: لا يوجد | N36: رياضيه جدا | O36: 31512120111921 | R36: =VLOOKUP(DataBase[[#This Row],[الفصل]],المرحلة_الدراسية[],2,0) -> الخامس الابتدائي | XFC36: =VLOOKUP(COUNTIF($XFD$2:XFD36,250001),Table3[],2,0) -> A_ | XFD36: =IF(XFD35+1=260000,250001,XFD35+1) -> 250035
A37: 45703.555 | B37: marim.shehata1990@gmail.com | C37: =_xlfn.CONCAT(XFC37:XFD37) -> A_250036 | D37: كارلا ناروز موريس | E37: Carla narouz mories | F37: الثالث الابتدائي | G37: 42963 | H37: صاحب شركه الترا للمقاولات | I37: معلمه | J37: 01280444102 | K37: 01285521965 | L37: كمبوند سكن مصر العبور الجديده عماره 16 | M37: لا | N37: التلوين ورياضه الجمباز والابتكار | O37: 31708160100401 | R37: =VLOOKUP(DataBase[[#This Row],[الفصل]],المرحلة_الدراسية[],2,0) -> الرابع الابتدائي | XFC37: =VLOOKUP(COUNTIF($XFD$2:XFD37,250001),Table3[],2,0) -> A_ | XFD37: =IF(XFD36+1=260000,250001,XFD36+1) -> 250036
A38: 45703.558 | B38: doaamosaadaboatallah42@gmail.com | C38: =_xlfn.CONCAT(XFC38:XFD38) -> A_250037 | D38: ريم ايهاب اسماعيل ممدوح | E38: Reem Ehab Ismail madouh | F38: الثالث الاعدادي | G38: 40606 | H38: محاسب | I38: محاسبه | J38: 01001390610 | K38: 01097908246 | L38: مدينه العبور الحي الثالث شارع الشهيد سعد عطا عماره رقم ١ علي اليمين الدور التاني شقه ٦ | M38: لايوجد | N38: التلوين | O38: 31103040100441 | R38: =VLOOKUP(DataBase[[#This Row],[الفصل]],المرحلة_الدراسية[],2,0) -> الأول الثانوي | XFC38: =VLOOKUP(COUNTIF($XFD$2:XFD38,250001),Table3[],2,0) -> A_ | XFD38: =IF(XFD37+1=260000,250001,XFD37+1) -> 250037
A39: 45703.558 | B39: mahamema649@gmail.com | C39: =_xlfn.CONCAT(XFC39:XFD39) -> A_250038 | D39: لارا محمود مصطفى احمد | E39: Lara Mahmoud mostafa ahmed | F39: الثالث الابتدائي | G39: 42758 | H39: ظابط شرطه | I39: لا تعمل | J39: 01221377617 | K39: 01123262231 | L39: العبور الحي السابع بلوك ١٥٠٩١ فيلا ١٣ بجوار مسجد الشيخ ايمن | M39: لا | N39: لا | O39: 31701230107021 | R39: =VLOOKUP(DataBase[[#This Row],[الفصل]],المرحلة_الدراسية[],2,0) -> الرابع الابتدائي | XFC39: =VLOOKUP(COUNTIF($XFD$2:XFD39,250001),Table3[],2,0) -> A_ | XFD39: =IF(XFD38+1=260000,250001,XFD38+1) -> 250038
A40: 45703.559 | B40: maggy.nabil87@gmail.com | C40: =_xlfn.CONCAT(XFC40:XFD40) -> A_250039 | D40: يوستينا جورج عادل ادوار | E40: Youstina George Adel Edwar | F40: الثالث الابتدائي | G40: 43002 | H40: محاسب | I40: طبيبة بيطريه | J40: 01005656568 | K40: 01225656567 | L40: بلوك ١٦٠٧٩ قطعه خامسه ، الحى الخامس ، العبور | M40: لا يوجد | N40: الاعمال اليدويه و الغناء بالكورال | O40: 31709240101464 | R40: =VLOOKUP(DataBase[[#This Row],[الفصل]],المرحلة_الدراسية[],2,0) -> الرابع الابتدائي | XFC40: =VLOOKUP(COUNTIF($XFD$2:XFD40,250001),Table3[],2,0) -> A_ | XFD40: =IF(XFD39+1=260000,250001,XFD39+1) -> 250039
A41: 45703.559 | B41: ashraf_ashi@hotmail.com | C41: =_xlfn.CONCAT(XFC41:XFD41) -> A_250040 | D41: فريده اشرف حامد محمود الكيلاني | E41: Farida Ashraf Hamed Mahmoud El-kelany | F41: الرابع الابتدائي | G41: 42302 | H41: محاسب | I41: دكتور تحاليل | J41: 01006044211 | K41: 01069618951 | L41: مدينة العبور الحي التاني محلية ٣٤ ج شارع ١٦قطعه ٧٩ | M41: لايوجد | N41: الرسم | O41: 31510251400144 | R41: =VLOOKUP(DataBase[[#This Row],[الفصل]],المرحلة_الدراسية[],2,0) -> الخامس الابتدائي | XFC41: =VLOOKUP(COUNTIF($XFD$2:XFD41,250001),Table3[],2,0) -> A_ | XFD41: =IF(XFD40+1=260000,250001,XFD40+1) -> 250040
A42: 45703.559 | B42: menna.magdy.87.83@gmail.com | C42: =_xlfn.CONCAT(XFC42:XFD42) -> A_250041 | D42: سدرة مصطفى أحمد الصاوي | E42: Sedra Mostafa Ahmed el Sawy | F42: الرابع الابتدائي | G42: 42406 | H42: رئيس نيابة إدارية | I42: ربة منزل | J42: 01113467895 | K42: 01111656908 | L42: العبور الحى التاسع كمبوند دار مصر المرحله الثانيه عماره ٤٥ الدور الأرضى شقه ٢ | M42: لا يوجد | N42: الرسم التمثيل الأعمال اليدوية ممارسه رياضه الجمباز الإيقاعي | O42: 31602060102048 | R42: =VLOOKUP(DataBase[[#This Row],[الفصل]],المرحلة_الدراسية[],2,0) -> الخامس الابتدائي | XFC42: =VLOOKUP(COUNTIF($XFD$2:XFD42,250001),Table3[],2,0) -> A_ | XFD42: =IF(XFD41+1=260000,250001,XFD41+1) -> 250041
A43: 45703.563 | B43: dalashker82@gmail.com | C43: =_xlfn.CONCAT(XFC43:XFD43) -> A_250042 | D43: تاليه عماد صابر الشامي | E43: Talia emad saber elshamy | F43: الخامس الابتدائي | G43: 38268 | H43: ضابط يالقوات الجويه | I43: مديرة مرحله في مدرسه مودرن افينيو | J43: 01006069764 | K43: 01003500659 | L43: مدينه العبور الحي التاسع شارع سليمان نجيب ١٨٠٢٢ قطعه ٨ الدور الارضي | M43: لا يوجد | N43: الرسم | R43: =VLOOKUP(DataBase[[#This Row],[الفصل]],المرحلة_الدراسية[],2,0) -> السادس الابتدائي | XFC43: =VLOOKUP(COUNTIF($XFD$2:XFD43,250001),Table3[],2,0) -> A_ | XFD43: =IF(XFD42+1=260000,250001,XFD42+1) -> 250042
A44: 45703.564 | B44: kokomamy2008@gmail.com | C44: =_xlfn.CONCAT(XFC44:XFD44) -> A_250043 | D44: مابيل صموئيل بشري أيوب | E44: Mabelle Samuel Boshra Ayoub | F44: الرابع الابتدائي | G44: 42318 | H44: IT manager at EKB brokerage company | I44: Sales manager at delta life Assurance | J44: 01201440143 | K44: 01006887696 | L44: ڤيلا 6 مربع 15043 شارع حسن مأمون الحي السابع مدينة العبور | M44: لا يوجد | N44: الرسم والأعمال الفنية | O44: 31511100100625 | R44: =VLOOKUP(DataBase[[#This Row],[الفصل]],المرحلة_الدراسية[],2,0) -> الخامس الابتدائي | XFC44: =VLOOKUP(COUNTIF($XFD$2:XFD44,250001),Table3[],2,0) -> A_ | XFD44: =IF(XFD43+1=260000,250001,XFD43+1) -> 250043
A45: 45703.565 | B45: hedy.karim.essam.mohamed@saint-joseph-school.com | C45: =_xlfn.CONCAT(XFC45:XFD45) -> A_250044 | D45: هيدي كريم عصام محمد | E45: Hedy Karim Essam Mohammed | F45: الرابع الابتدائي | G45: 42414 | H45: Broker in Egyptian stock | I45: Housewife | J45: 01120055522 | K45: 01102118835 | L45: 18045 villa 14 Zakria ahmed st, 9th district, obour city | M45: No | N45: الرياضه ، حب التنسيق بين الالوان ودمجها، قراءه القصص بالانجلش والعربي | O45: 31602140108985 | R45: =VLOOKUP(DataBase[[#This Row],[الفصل]],المرحلة_الدراسية[],2,0) -> الخامس الابتدائي | XFC45: =VLOOKUP(COUNTIF($XFD$2:XFD45,250001),Table3[],2,0) -> A_ | XFD45: =IF(XFD44+1=260000,250001,XFD44+1) -> 250044
A46: 45703.566 | B46: marinamagdi26@gmail.com | C46: =_xlfn.CONCAT(XFC46:XFD46) -> A_250045 | D46: ميراي بيتر نبيل ثابت | E46: Meraie Peter Nabil Thabet | F46: الرابع الابتدائي | G46: 42533 | H46: Business man | I46: House wife | J46: 01220222288 | K46: 01008499460 | L46: 12 سكن مصر العبور الجديده شقة 15 | M46: لايوجد | N46: الرسم ، التلوين ،الموسيقي، التنس ،السباحة | O46: 31606120105608 | R46: =VLOOKUP(DataBase[[#This Row],[الفصل]],المرحلة_الدراسية[],2,0) -> الخامس الابتدائي | XFC46: =VLOOKUP(COUNTIF($XFD$2:XFD46,250001),Table3[],2,0) -> A_ | XFD46: =IF(XFD45+1=260000,250001,XFD45+1) -> 250045
A47: 45703.568 | B47: dina.asp.portal@gmail.com | C47: =_xlfn.CONCAT(XFC47:XFD47) -> A_250046 | D47: جودي محمد طلعت | E47: Jodie mohamed talaat | F47: الثاني الاعدادي | G47: 40986 | H47: مهندس | I47: مهندسة | J47: 01000072045 | K47: 01281230030 | L47: مدينه العبور الحي السادس بلوك 14049 فيلا 17 | M47: لا يوجد | N47: كرة باسكت و برمجة | O47: 31203180101124 | R47: =VLOOKUP(DataBase[[#This Row],[الفصل]],المرحلة_الدراسية[],2,0) -> الثالث الاعدادي | XFC47: =VLOOKUP(COUNTIF($XFD$2:XFD47,250001),Table3[],2,0) -> A_ | XFD47: =IF(XFD46+1=260000,250001,XFD46+1) -> 250046
A48: 45703.57 | B48: mohamadtalaat@gmail.com | C48: =_xlfn.CONCAT(XFC48:XFD48) -> A_250047 | D48: مريم محمد طلعت | E48: Mariam mohamed Talaat | F48: الخامس الابتدائي | G48: 41998 | H48: مهندس | I48: مهندسة | J48: 01000072045 | K48: 01281230030 | L48: مدينه العبور الحي السادس بلوك ١٤٠٤٩ فيلا ١٧ | M48: لا يوجد | N48: باليه و رسم | O48: 31412250103942 | R48: =VLOOKUP(DataBase[[#This Row],[الفصل]],المرحلة_الدراسية[],2,0) -> السادس الابتدائي | XFC48: =VLOOKUP(COUNTIF($XFD$2:XFD48,250001),Table3[],2,0) -> A_ | XFD48: =IF(XFD47+1=260000,250001,XFD47+1) -> 250047
...

Sheet Database_Backup
A1: Timestamp | B1: Email Address | C1: اسم الطالبة رباعيًا | D1: اسم الطالبة باللغة الانجليزية | E1: الفصل | F1: تـاريخ الميلاد | G1: وظيفـة الأب | H1: وظيفــة الأم | I1: موبـايل الأب | J1: موبـايل الأم | K1: العنوان بالتفصيل | L1: التنويه لوجود أى حالة مرضية | M1: المواهب و المهارات
A2: 45703.506 | B2: nerminsayed450@gmail.com | C2: هيڤين ياسر السيد قطب | D2: Heaven Yasser El Sayed Kotb | E2: الرابع الابتدائي | F2: 41667 | G2: محاسب | H2: مدرسة | I2: 01032677148 | J2: 01014306267 | K2: العبور الحي التاسع شارع عبد العزيز الشوان متفرع من شارع الجامعة بلوك 82 عمارة 5 الدور التالت شقة 8 | L2: لا يوجد | M2: الرسم ولعب الباسكت
A3: 45703.51 | B3: rehammagdy214@gmail.com | C3: ترينتى رجائى نسيم ملك | D3: Trinity Ragaay Nessim malak | E3: الرابع الابتدائي | F3: 41641 | G3: محامي | H3: محامية | I3: 1225970823 | J3: 1272995022 | K3: دار مصر المرحله التانيه الحى التاسع العبور | L3: حساسية صدر | M3: التمثيل.. كورال... رسم..تفصيل... اعمال فنيه
A4: 45703.511 | B4: marymelek777@gmail.com | C4: مارينا ملك بخيت ملك | D4: Marina Melek Bekhit Melek | E4: السادس الابتدائي | F4: 40977 | G4: محاسب شركة انسيا | H4: طبيبة بيطرية | I4: 01223366700 | J4: 01205080177 | K4: 24جولدن هاوس المستثمر الصغير خلف القديس يوسف | L4: لا يوجد | M4: القيادة والصوت الجميل
A5: 45703.512 | B5: marinajunier89@gmail.com | C5: جونير بيشوى ظريف | D5: Junier Beshoy Zarif | E5: الرابع الابتدائي | F5: 41849 | G5: صاحب شركه موازين | H5: Sales international at spicekingdom | I5: 01254333987 | J5: 01277035552 | K5: العبور الحى التانى فيلا ٨٤ أمام المرور | L5: لا يوجد | M5: تمثيل و التلوين
A6: 45703.515 | B6: aivywael630@gmail.com | C6: ايڤى وائل موريس ابادير | D6: Aivy wael Morris abadeer | E6: الرابع الابتدائي | F6: 41886 | G6: مدير فى شركة الميرى للأدوية | H6: محاسبة بالشركة المصرية للإتصالات | I6: 01221212417 | J6: 01552204480 | K6: ٢٠ ش عمار بن ياسر خلف المرور مدينة السلام | L6: لا يوجد | M6: الرسم
A7: 45703.518 | B7: marwaalshall2@gmail.com | C7: ملك أشرف حامد الكيلاني | D7: Malak Ashraf Hamed Elkelany | E7: الخامس الابتدائي | F7: 41228 | G7: محاسب بشركه شمال القاهره للكهرباء | H7: أخصائي تحاليل طبيه بمعامل البرج | I7: 01006044211 | J7: 01225643326 | K7: العبور الحي الثاني محليه 34 شارع 16 قطعه 79 | L7: نزيف من الانف | M7: قراءه برمجه
A8: 45703.522 | B8: marmartony2014@gmail.com | C8: ايرينى مجدى شوقى انطون | D8: Eriny Magdy shawky anton | E8: الرابع الابتدائي | F8: 41852 | G8: صاحب محل موبايلات | H8: ربه منزل | I8: 01050006424 | J8: 01275561556 | K8: 78 شارع الجامع قباء جسر السويس | L8: لا يوجد | M8: التمثيل
A9: 45703.53 | B9: hova.george2014@gmail.com | C9: هيفين جورج حنا سليمان | D9: Heaven George | E9: الرابع الابتدائي | F9: 41905 | G9: محاسب | H9: ادارية في شركة طيران | I9: 01225228920 | J9: 01227774987 | K9: 59 تعاونيات شيراتون الدور ال3شقة 11 | L9: لا | M9: الجمباز و الرسم
A10: 45703.532 | B10: nadia7.2014@gmail.com | C10: ناديا احمد وجدي السنوسي | D10: Nadeia Ahmed Wagdy Elsnosy | E10: الخامس الابتدائي | F10: 41470 | G10: مدير فرع الشركة الاماراتيه للتامين | H10: مهندسة معماريه | I10: 01090999350 | J10: 01022833025 | K10: شارع 50 الحي الاول عمارة 2 مدينة العبور | L10: لا يوجد | M10: سباحه وتلوين
A11: 45703.533 | B11: marinamelek4@gmail.com | C11: مهرائيل ملك بخيت ملك | D11: Mehrail Melek Bekhit Melek | E11: الرابع الابتدائي | F11: 41679 | G11: محاسب في شركة انسيا | H11: طبيبة بيطرية | I11: 01223366700 | J11: 01205080177 | K11: 24جولدن هاوس المستثمر الصغير خلف القديس يوسف العبور | L11: لا يوجد | M11: الصوت الجميل والقيادة
A12: 45703.536 | B12: marselle.zarif@saint-joseph-school.com | C12: بيرلا الهامي بخيت فكري | D12: Perla Elhamy Bekhet Fekry | E12: الرابع الابتدائي | F12: 41781 | G12: صاحب مطعم | H12: مدرسة | I12: 01202069472 | J12: 01203187262 | K12: 198شارع 31 الشباب مدينه العبور | L12: لا بوجد | M12: الرسم
A13: 45705.835 | B13: chantal.shenouda.zarif.riad@saint-joseph-school.com | C13: شانتال شنودة ظريف رياض | D13: Chantal shenouda zarif riad | E13: الرابع الابتدائي | F13: 41591 | G13: مدير مبيعات مصنع كيروماربل للرخام والجرانيت | H13: طبيبة بيطرية واخصائى تحاليل طبية | I13: 01275155297 | J13: 01279000095 | K13: العبور الحى التالت بلوك ٢٨٠٣٣ عمارة ١٥ شارع محمد وحيد عبد الخالق الدور الاخير | L13: لا يوجد | M13: باسكت وسباحة وبيانو
A14: 45703.538 | B14: rashajojo101@gmail.com | C14: جولى جورج عوض جرجس | D14: Julie George Awad Gergis | E14: الثالث الابتدائي | F14: 42031 | G14: مرشد سياحى | H14: دكتورة بكلية الآثار جامعة عين شمس | I14: 1278297133 | J14: 1289874445 | K14: العبور الحى الاول محلية ٦ | L14: لا يوجد | M14: الجمباز والتمثيل والاشغال اليدوية والغناء
A15: 45703.539 | B15: kokeadel387@gmail.com | C15: نيللي شادي محمد | D15: Nelly shady mohamed | E15: الثاني الابتدائي | F15: 42382 | G15: اعمال حرة | H15: لا يوجد | I15: 01003666087 | J15: 01005202654 | K15: مدينة المستقبل امام اكوا بارك عمارة ٧٣٨ شقة ٢٤ | L15: لا يوجد | M15: رياضة الجمباز
A16: 45703.539 | B16: mosherasobhy@hotmail.com | C16: مريم وسام لويس شفيق | D16: Mariam wesam louis shafik | E16: الثالث الابتدائي | F16: 42129 | G16: The owner of Trianto holidays company | H16: Tourism manager at flamingo travel | I16: 01223620949 | J16: 01276758324 | K16: فيلا ٦٦ البنفسج ٤ التجمع الاول القاهرة الجديدة | L16: لا يوجد | M16: رسم - تلوين - أعمال فنية يدوية - كتابة القصص
A17: 45703.539 | B17: bassantromany@gmail.com | C17: بريتي سامي أنور عدلي | D17: Pretty sami Anwar adly | E17: الاول الابتدائي | F17: 42840 | G17: مهندس | H17: مدرسه | I17: 01288236660 | J17: 01227524446 | K17: الحي التاني العبور | L17: لا | M17: الرسم والتلوين
A18: 45703.539 | B18: ahmedsherif708@gmail.com | C18: جوزيدا أحمد محمد ابراهيم | D18: Gozida ahmed mohamed ibrahim | E18: الاول الابتدائي | F18: 42685 | G18: Accountant | H18: Not working | I18: +201094676545 | J18: +201003606129 | K18: مدينه حتب اكتوبر طريق مصر الإسماعيلية شارع ١٦ لوك ٢٢ عماره ١١ | L18: لا يوجد | M18: الجمباز / الرسم
A19: 45703.539 | B19: lomena.hossam.rashad.gergs@saint-joseph-school.com | C19: لومينا حسام رشاد جرجس | D19: Lomena Hossam Rashad Gergs | E19: الاول الابتدائي | F19: 42670 | G19: مهندس ميكانيكا سيارات حر | H19: ربه منزل | I19: 01026433446 | J19: 1023477168 | K19: الحي الثاني بجوار مدرسه ستان فورد الدوليه فيلا رقم 115 | L19: وجود حساسيه علي الصدر | M19: الرقص الغناء التمثيل المحاوره
A20: 45703.539 | B20: babyborn1982@gmail.com | C20: هولي رضا ناروز جرجس | D20: Holly reda narouz girges | E20: الثاني الابتدائي | F20: 46019 | G20: محاسب و رئيس قسم التخصيمات والشحن بشركه صناعه وسائل النقل | H20: باحثة شرطه بالاداره العامه لشرطه ميناء القاهره الجوي | I20: 01223912711 | J20: 01271066601 | K20: 34 شارع نورالدين الزيتون امام سنترال مصر الجديده | L20: لا يوجد | M20: جمباز و متوقف حاليا
A21: 45703.54 | B21: asamy1500@gmail.com | C21: لوسيندا أحمد سامى عبد الحليم محمد | D21: Lucienda Ahmed Samy Abdelhalem Mohamed | E21: الثالث الابتدائي | F21: 41988 | G21: مهندس بالشركه الوطنيه للغاز | H21: شئون طلبه بمدرسه نايل صانز الدوليه ( قسم الأمريكان ) | I21: 01271234485 | J21: 01211794485 | K21: قطعة ٣ بلوك ٢٨٠٣٧ الحى ٣ مدينه العبور | L21: لا | M21: التلوين
A22: 45703.54 | B22: evaa.mohy@gmail.com | C22: ايلينا ملاك ادوارد عزيز | D22: Elina malak Edward aziz | E22: الاول الابتدائي | F22: 42733 | G22: مدير مبيعات شركه ستيل دور ابواب مصفحه | H22: مهندسه | I22: +20 120 0748223 | J22: 01228306158 | K22: 472 حي المجد العبور الجديده بجوار بنزينه بترومين | L22: لا | M22: الرسم والرقص والتلوين
A23: 45703.541 | B23: annamaria.romani11@gmail.com | C23: اناماريا رومانى تحسين صادق | D23: Annamaria Romani Tahsin Sadek | E23: الرابع الابتدائي | F23: 41640 | G23: مدير تسويق ومبيعات | H23: شئون عاملين | I23: 0097333127277 | J23: 01277621921 | K23: عمارة ١٤٧شارع الشباب اخر السبعين متر | L23: لا يوجد | M23: موسيقى
A24: 45703.541 | B24: malik.tokyo.oms@gmail.com | C24: مليكه محمد عبد المعز ابراهيم | D24: Malika Mohamed abdelmoaz Ibrahim | E24: الثاني الابتدائي | F24: 42393 | G24: باحث في هيئه الاستثمار وحاصل على دكتوراه في مجال اداره الاعمال | H24: ربه منزل | I24: 01061744447 | J24: 01018702203 | K24: العبور الحي الخامس | L24: لايوجد | M24: الرسم والغناء والسباحه
A25: 45703.542 | B25: madonnageorge1511@gmail.com | C25: جونير مايكل عزيز أنيس | D25: Junir Michael Aziz Anis | E25: الثالث الابتدائي | F25: 42033 | G25: رئيس قسم المبيعات في شركه مرسيدس Mcv | H25: ربه منزل | I25: 01273937763 | J25: 01270317462 | K25: كمبوند جنة مصر عماره ٨ شقه ١٠ مدينه العبور الحي التاني شارع احمد بن طولون | L25: لا | M25: التلوين
A26: 45703.543 | B26: sallyadel198817@gmail.com | C26: لافيرا مايكل ظريف مليح | D26: Lavera Michael zaref maleh | E26: الاول الابتدائي | F26: 42656 | G26: رئيس قسم في شركه Mcv | H26: باحثه شرطه في شرطه تعمير جهاز مدينه العبور | I26: 0120 4690260 | J26: 01207664336 | K26: فيلا ١/١٢ج شارع ٢٧ محليه ١٢ الحي الاول مدينه العبور | L26: لايوجد | M26: حصلت علي ٣ ميداليات ذهبيه واحده برونز في جمباز الايروبيك و بتحب الرسم
A27: 45703.543 | B27: salwamagmou3a@gmail.com | C27: ملك محمد ابراهيم سعد الدين | D27: malak mohamed ibrahim saad el dein | E27: الثالث الابتدائي | F27: 42046 | G27: die | H27: Merchandiser | I27: 01027734459 | J27: 01027734457 | K27: 132B first district mahaliya 8 abour city | L27: no | M27: basketball
A28: 45703.543 | B28: yarashalash@gmail.com | C28: مليكة ضياء الدين محمود عبد العزيز | D28: Maleeka Diaa Eldeen Mahmoud Abdelaziz | E28: الاول الابتدائي | F28: 43075 | G28: ضابط شرطة | H28: صيدلانية | I28: 01144170457 | J28: 01112975553 | K28: الحي الاول-محلية ١٢-٤٨ ش سلمان فارسي-مدينه العبور | L28: لا يوجد | M28: الرسم-التفاوض-توزيع المهام-العمل في فريق-الادارة الجيدة
A29: 45703.544 | B29: mariam.mokhles89@gmail.com | C29: سيلينا جوزيف جمال أمين | D29: Celina Joseph gamal amen | E29: الاول الابتدائي | F29: 42690 | G29: دكتور علاج طبيعى | H29: دكتورة علاج طبيعى | I29: 01228346734 | J29: 01287328606 | K29: مدينة المستقبل طريق مصر الإسماعيلية الصحراوى. قطاع اليو عمارة ٢٤ الدور الأول شقة ١٣ | L29: لا يوجد الحمد الله | M29: التلوين والرسم
A30: 45703.544 | B30: basmarefaat305@gmail.com | C30: فريدة محمد القصبي | D30: Farida Mohamed Qasby | E30: الاول الابتدائي | F30: 42923 | G30: ظابط | H30: دكتورة | I30: 01010105752 | J30: 01029755557 | K30: مدينة مستقبل الهابكستب عمارة ٤٢٨ شقة ٦٢ | L30: لا يوجد | M30: اسكواش وسباحة ورسم
A31: 45703.545 | B31: christinagamal367@gmail.com | C31: ماريتسيا سامح بطرس عبدالله | D31: Maritsia sameh botros Abdulla | E31: الرابع الابتدائي | F31: 41579 | G31: مهندس | H31: مدرسه | I31: 01227656913 | J31: 01098550901 | K31: العبور الجديدة حى الكرامه ع 203 ش 11 | L31: لا يوجد | M31: رسم وعمل مجسمات اعمال فنيه ولعب كره السله
... A36: 45703.554 | B36: mira.m.mansour@gmail.com | C36: لورين خالد علي علي | D36: Lauren khaled ali ali | E36: الثاني الابتدائي | F36: 42350 | G36: لواء شرطه | H36: استشاري في الاتفاقيات التجاري الدوليه بالهيئة العامة للرقابه علي الصادرات | I36: 010 | J36: 01282633328 | K36: مدينه العبور الحى السابع شارع الشهيد بدر رخا مربع 15035 فيلا 14 | L36: لا يوجد | M36: رياضيه جدا
A37: 45703.555 | B37: marim.shehata1990@gmail.com | C37: كارلا ناروز موريس سمير | D37: Carla narouz mories | E37: الاول الابتدائي | F37: 42963 | G37: صاحب شركه الترا للمقاولات | H37: معلمه | I37: 1280444102 | J37: 01285521965 | K37: كمبوند سكن مصر العبور الجديده عماره 16 | L37: لا | M37: التلوين ورياضه الجمباز والابتكار
A38: 45703.558 | B38: doaamosaadaboatallah42@gmail.com | C38: ريم ايهاب اسماعيل ممدوح | D38: Reem Ehab Ismail madouh | E38: الاول الاعدادي | F38: 40606 | G38: محاسب | H38: محاسبه | I38: 1001390610 | J38: 1097908246 | K38: مدينه العبور الحي الثالث شارع الشهيد سعد عطا عماره رقم ١ علي اليمين الدور التاني شقه ٦ | L38: لايوجد | M38: التلوين
A39: 45703.558 | B39: mahamema649@gmail.com | C39: لارا محمود مصطفى احمد | D39: Lara Mahmoud mostafa ahmed | E39: الاول الابتدائي | F39: 42758 | G39: ظابط شرطه | H39: لا تعمل | I39: 01221377617 | J39: 1123262231 | K39: العبور الحي السابع بلوك ١٥٠٩١ فيلا ١٣ بجوار مسجد الشيخ ايمن | L39: لا | M39: لا
A40: 45703.559 | B40: maggy.nabil87@gmail.com | C40: يوستينا جورج عادل ادوار | D40: Youstina George Adel Edwar | E40: الاول الابتدائي | F40: 43002 | G40: محاسب | H40: طبيبة بيطريه | I40: 01005656568 | J40: 01225656567 | K40: بلوك ١٦٠٧٩ قطعه خامسه ، الحى الخامس ، العبور | L40: لا يوجد | M40: الاعمال اليدويه و الغناء بالكورال
A41: 45703.559 | B41: ashraf_ashi@hotmail.com | C41: فريده اشرف حامد محمود الكيلاني | D41: Farida Ashraf Hamed Mahmoud El-kelany | E41: الثاني الابتدائي | F41: 42302 | G41: محاسب | H41: دكتور تحاليل | I41: 01006044211 | J41: 01069618951 | K41: مدينة العبور الحي التاني محلية ٣٤ ج شارع ١٦قطعه ٧٩ | L41: لايوجد | M41: الرسم
A42: 45703.559 | B42: menna.magdy.87.83@gmail.com | C42: سدرة مصطفى أحمد الصاوي | D42: Sedra Mostafa Ahmed el Sawy | E42: الثاني الابتدائي | F42: 42406 | G42: رئيس نيابة إدارية | H42: ربة منزل | I42: 01113467895 | J42: 01111656908 | K42: العبور الحى التاسع كمبوند دار مصر المرحله الثانيه عماره ٤٥ الدور الأرضى شقه ٢ | L42: لا يوجد | M42: الرسم التمثيل الأعمال اليدوية ممارسه رياضه الجمباز الإيقاعي
A43: 45703.563 | B43: dalashker82@gmail.com | C43: تاليه عماد صابر الشامي | D43: Talia emad saber elshamy | E43: الثالث الابتدائي | F43: 38268 | G43: ضابط يالقوات الجويه | H43: مديرة مرحله في مدرسه مودرن افينيو | I43: 1006069764 | J43: 1003500659 | K43: مدينه العبور الحي التاسع شارع سليمان نجيب ١٨٠٢٢ قطعه ٨ الدور الارضي | L43: لا يوجد | M43: الرسم
A44: 45703.564 | B44: kokomamy2008@gmail.com | C44: مابيل صموئيل بشري أيوب | D44: Mabelle Samuel Boshra Ayoub | E44: الثاني الابتدائي | F44: 42318 | G44: IT manager at EKB brokerage company | H44: Sales manager at delta life Assurance | I44: 01201440143 | J44: 01006887696 | K44: ڤيلا 6 مربع 15043 شارع حسن مأمون الحي السابع مدينة العبور | L44: لا يوجد | M44: الرسم والأعمال الفنية
...

Sheet Stat
A1: الفصل | B1: Count | D1: المرحلة | E1: Count
A2: الاول الابتدائي | B2: =COUNTIF(DataBase[الفصل],Stat!A2) -> 0 | D2: زهرات | E2: =SUM(B2:B4) -> 56
A3: الثاني الابتدائي | B3: =COUNTIF(DataBase[الفصل],Stat!A3) -> 0 | D3: مرشدات | E3: =SUM(B5:B9) -> 215
A4: الثالث الابتدائي | B4: =COUNTIF(DataBase[الفصل],Stat!A4) -> 56 | D4: جوالة | E4: =SUM(B10:B11) -> 11
A5: الرابع الابتدائي | B5: =COUNTIF(DataBase[الفصل],Stat!A5) -> 49 | D5: Total | E5: =SUM(E2:E4) -> 282
A6: الخامس الابتدائي | B6: =COUNTIF(DataBase[الفصل],Stat!A6) -> 53 | E6: =E5-B12 -> 0
A7: السادس الابتدائي | B7: =COUNTIF(DataBase[الفصل],Stat!A7) -> 41
A8: الاول الاعدادي | B8: =COUNTIF(DataBase[الفصل],Stat!A8) -> 38
A9: الثاني الاعدادي | B9: =COUNTIF(DataBase[الفصل],Stat!A9) -> 34
A10: الثالث الاعدادي | B10: =COUNTIF(DataBase[الفصل],Stat!A10) -> 11
A11: الثانى الثانوى | B11: =COUNTIF(DataBase[الفصل],Stat!A11) -> 0
A12: Total | B12: =SUM(B2:B11) -> 282

Sheet Pivot
A3: الصف | B3: اسم الطالبة رباعيًا | C3: موبـايل الأم
A4: الاول الاعدادي | B4: بسنت احمد محمود محمد | C4: 01066307888
A5: الاول الاعدادي | B5: جويس رضا ناروز جرجس | C5: 01271066601
A6: الاول الاعدادي | B6: دارين أيمن السيد أحمد | C6: 01023692086
A7: الاول الاعدادي | B7: ريم ايهاب اسماعيل ممدوح | C7: 01097908246
A8: الاول الاعدادي | B8: ماريه محمد محمود عبد المنعم احمد محمد | C8: 01002943629
A9: الاول الاعدادي | B9: مانويلا أيوب خلف ايوب | C9: 01279616006
A10: الاول الاعدادي | B10: ميرولا يسري عبيد مكرم | C10: 01203890675
A11: الاول الاعدادي | B11: هولي هاني موريس عجيب | C11: 01226926912
A12: الثاني الاعدادي | B12: ايلاريا عادل جورج ايليا | C12: 01282222551
A13: الثاني الاعدادي | B13: جونير مدحت منير شفيق | C13: 01148793493
A14: الثاني الاعدادي | B14: روان شريف سيد نجدي | C14: 01063010830
... A28: الثالث الاعدادي | B28: ناتالي رضا ناروز جرجس | C28: 01271066601
A29: Grand Total
